Workbook

Sheet youtube_video_data
A1: Video ID | B1: URL | C1: Title
A2: honflNZTKHk | B2: =_xlfn.XLOOKUP(A2,[1]Sheet1!$C:$C,[1]Sheet1!$A:$A) -> #N/A | C2: Instrumental - Deewaar (1975) - 'I'm Falling In Love With A Stranger'
A3: uQvOHHGrMjg | B3: =_xlfn.XLOOKUP(A3,[1]Sheet1!$C:$C,[1]Sheet1!$A:$A) -> #N/A | C3: *****R.D.BURMAN BOSS Special***** SAAGAR Theme*** H D audio
A4: pHJiYu69C4c | B4: =_xlfn.XLOOKUP(A4,[1]Sheet1!$C:$C,[1]Sheet1!$A:$A) -> #N/A | C4: Babu (henchman) entry | Unique background music | Gargling | Anette Pinto | R D Burman
A5: PBLmRYnFs7E | B5: =_xlfn.XLOOKUP(A5,[1]Sheet1!$C:$C,[1]Sheet1!$A:$A) -> #N/A | C5: Chase Music of Film Arjun 1985 ||MUSIC by R D Burman
A6: CpYuH4Cc8Mk | B6: =_xlfn.XLOOKUP(A6,[1]Sheet1!$C:$C,[1]Sheet1!$A:$A) -> https://youtu.be/CpYuH4Cc8Mk?si=qK5iGgqa3qsPRKH0 | C6: Rah Pe Rehte Hai | Namkeen ( 1982 ) | D6: =_xlfn.XLOOKUP(B6,Sheet2!B:B,Sheet2!D:D) -> Song 01
A7: C1w6p3TEVxI | B7: =_xlfn.XLOOKUP(A7,[1]Sheet1!$C:$C,[1]Sheet1!$A:$A) -> https://youtu.be/C1w6p3TEVxI?si=CkHwXCKJOBhZwWkK | C7: Aye Zindagi Hui Kahan Bhool Jiski | (Namumkin 1988) | D7: =_xlfn.XLOOKUP(B7,Sheet2!B:B,Sheet2!D:D) -> Song 02
A8: WaCRlPUPLhk | B8: =_xlfn.XLOOKUP(A8,[1]Sheet1!$C:$C,[1]Sheet1!$A:$A) -> https://youtu.be/WaCRlPUPLhk?si=Nq_DXLhf7aS2DjGu | C8: Na Jaane Din Kaise (Both Parts) | (Chala Murari Hero Banne 1977) | D8: =_xlfn.XLOOKUP(B8,Sheet2!B:B,Sheet2!D:D) -> Song 03
A9: PleWU2pdK-I | B9: =_xlfn.XLOOKUP(A9,[1]Sheet1!$C:$C,[1]Sheet1!$A:$A) -> https://youtu.be/PleWU2pdK-I?si=PK_rAjjC72uEVZrZ | C9: Main Shayar Badnam | (Namak Haraam 1973) | D9: =_xlfn.XLOOKUP(B9,Sheet2!B:B,Sheet2!D:D) -> Song 04
A10: xkQpfIMj1UE | B10: =_xlfn.XLOOKUP(A10,[1]Sheet1!$C:$C,[1]Sheet1!$A:$A) -> https://youtu.be/xkQpfIMj1UE?si=RerH28vnO62xX_s6 | C10: Mujhko Yuhi Udaas | (Khushboo (1975) | D10: =_xlfn.XLOOKUP(B10,Sheet2!B:B,Sheet2!D:D) -> Song 05
A11: flFE-ps5yYo | B11: =_xlfn.XLOOKUP(A11,[1]Sheet1!$C:$C,[1]Sheet1!$A:$A) -> https://youtu.be/flFE-ps5yYo?si=C90tKlW2S2fhkswP | C11: Tumne Mujhe Dekha | (Teesri Manzil 1966) | D11: =_xlfn.XLOOKUP(B11,Sheet2!B:B,Sheet2!D:D) -> Song 06
A12: tC11eSDHobE | B12: =_xlfn.XLOOKUP(A12,[1]Sheet1!$C:$C,[1]Sheet1!$A:$A) -> https://youtu.be/tC11eSDHobE?si=LpParr0eIVJHpLeT | C12: A Ri Pawan Dhunde Kise Tera Mann | ( Bemisaal 1982) | D12: =_xlfn.XLOOKUP(B12,Sheet2!B:B,Sheet2!D:D) -> Song 07
A13: 2fUVcrMA8Dg | B13: =_xlfn.XLOOKUP(A13,[1]Sheet1!$C:$C,[1]Sheet1!$A:$A) -> https://youtu.be/2fUVcrMA8Dg?si=bXt_fKwl3TEJiqiY | C13: Kisi Baat Pe Main Kisise Khafa Hoon | ( Bemisaal 1982) | D13: =_xlfn.XLOOKUP(B13,Sheet2!B:B,Sheet2!D:D) -> Song 08
A14: 0VbyQ5tdavI | B14: =_xlfn.XLOOKUP(A14,[1]Sheet1!$C:$C,[1]Sheet1!$A:$A) -> https://youtu.be/0VbyQ5tdavI?si=IP277RozQo8C-FBe | C14: Sawan Ke Jhoole| (Jurmana 1979) | D14: =_xlfn.XLOOKUP(B14,Sheet2!B:B,Sheet2!D:D) -> Song 09
A15: iaLmf7L-B24 | B15: =_xlfn.XLOOKUP(A15,[1]Sheet1!$C:$C,[1]Sheet1!$A:$A) -> https://youtu.be/iaLmf7L-B24?si=YV8cIZJ5yHJUapXE | C15: Oh Hansini | (Zehreela Insaan 1974) | D15: =_xlfn.XLOOKUP(B15,Sheet2!B:B,Sheet2!D:D) -> Song 10
A16: RscsV4uuetw | B16: =_xlfn.XLOOKUP(A16,[1]Sheet1!$C:$C,[1]Sheet1!$A:$A) -> https://youtu.be/RscsV4uuetw?si=HUEUjhme8qBCWgTd | C16: Jidhar Dekhoon Teri Tasveer | (Mahaan 1983) | D16: =_xlfn.XLOOKUP(B16,Sheet2!B:B,Sheet2!D:D) -> Song 11
A17: ADYDEx1pvEg | B17: =_xlfn.XLOOKUP(A17,[1]Sheet1!$C:$C,[1]Sheet1!$A:$A) -> https://youtu.be/ADYDEx1pvEg?si=WKjpAxfpZMgEWOOy | C17: KYA JAANU SAJAN HOTI HAI | (BAHARON KE SAPNE 1967) | D17: =_xlfn.XLOOKUP(B17,Sheet2!B:B,Sheet2!D:D) -> Song 12 | E17: =PROPER(C17) -> Kya Jaanu Sajan Hoti Hai | (Baharon Ke Sapne 1967)
A18: PZzK3CVzLKo | B18: =_xlfn.XLOOKUP(A18,[1]Sheet1!$C:$C,[1]Sheet1!$A:$A) -> https://youtu.be/PZzK3CVzLKo?si=y9ntwMjpZFCPp6dU | C18: Katra Katra Milti Hai Katra Katra Jeene Do | (Ijaazat 1987) | D18: =_xlfn.XLOOKUP(B18,Sheet2!B:B,Sheet2!D:D) -> Song 13
A19: wVlsl3QXwKU | B19: =_xlfn.XLOOKUP(A19,[1]Sheet1!$C:$C,[1]Sheet1!$A:$A) -> https://youtu.be/wVlsl3QXwKU?si=u-ReqZGUQX_0Gi36 | C19: Dhanno Ki Aankhon Me | (Kitaab 1977) | D19: =_xlfn.XLOOKUP(B19,Sheet2!B:B,Sheet2!D:D) -> Song 14
A20: M_mA1M44Bwc | B20: =_xlfn.XLOOKUP(A20,[1]Sheet1!$C:$C,[1]Sheet1!$A:$A) -> https://youtu.be/M_mA1M44Bwc?si=wwIEDgVbo6a2_DoT | C20: Subha Serial Title Song | (Subah 1987) | D20: =_xlfn.XLOOKUP(B20,Sheet2!B:B,Sheet2!D:D) -> Song 15
A21: t6iLjbkxBZo | B21: =_xlfn.XLOOKUP(A21,[1]Sheet1!$C:$C,[1]Sheet1!$A:$A) -> https://youtu.be/t6iLjbkxBZo?si=IZYjFNUaK22H1qlN | C21: Masterji ki aa gayi chitthi | (Kitaab 1977) | D21: =_xlfn.XLOOKUP(B21,Sheet2!B:B,Sheet2!D:D) -> Song 16
A22: 8t5Rt_LWmpE | B22: =_xlfn.XLOOKUP(A22,[1]Sheet1!$C:$C,[1]Sheet1!$A:$A) -> https://youtu.be/8t5Rt_LWmpE?si=cVRNkFxngFAPwxtq | C22: Samundar Mein Nahake | (Pukar 1983) | D22: =_xlfn.XLOOKUP(B22,Sheet2!B:B,Sheet2!D:D) -> Song 17
A23: h34dmUw_yCQ | B23: =_xlfn.XLOOKUP(A23,[1]Sheet1!$C:$C,[1]Sheet1!$A:$A) -> https://youtu.be/h34dmUw_yCQ?si=kBKlVoNxUkzEiJy3 | C23: Phir Wahi Raat | (Ghar 1978) | D23: =_xlfn.XLOOKUP(B23,Sheet2!B:B,Sheet2!D:D) -> Song 18
A24: kkTv_aUjd5Y | B24: =_xlfn.XLOOKUP(A24,[1]Sheet1!$C:$C,[1]Sheet1!$A:$A) -> https://youtu.be/kkTv_aUjd5Y?si=TCkKvKpl_76ovFE8 | C24: Phulon Ki Duniya Se | (Rickshawala 1973) | D24: =_xlfn.XLOOKUP(B24,Sheet2!B:B,Sheet2!D:D) -> Song 20
A25: wKnWL8-6qWA | B25: =_xlfn.XLOOKUP(A25,[1]Sheet1!$C:$C,[1]Sheet1!$A:$A) -> https://youtu.be/wKnWL8-6qWA?si=SqpxOfrM2GfL3Zbr | C25: Maine Kaha Zid Chhod | (Rickshawala 1973) | D25: =_xlfn.XLOOKUP(B25,Sheet2!B:B,Sheet2!D:D) -> Song 21
A26: lu5MjHcy6Lg | B26: =_xlfn.XLOOKUP(A26,[1]Sheet1!$C:$C,[1]Sheet1!$A:$A) -> https://youtu.be/lu5MjHcy6Lg?si=U_kUjhTdIKlHEPoE | C26: Ek Baat Dil Mein Aayi Hai | (Rahi Badal Gaye 1984) | D26: =_xlfn.XLOOKUP(B26,Sheet2!B:B,Sheet2!D:D) -> Song 22
A27: XI2P7HgHK9M | B27: =_xlfn.XLOOKUP(A27,[1]Sheet1!$C:$C,[1]Sheet1!$A:$A) -> https://youtu.be/XI2P7HgHK9M?si=dSGqPnPDrSF8l4r7 | C27: Silli Hawa Chhoo Gai | Libaas | D27: =_xlfn.XLOOKUP(B27,Sheet2!B:B,Sheet2!D:D) -> Song 23
A28: aWJc-cT12Mc | B28: =_xlfn.XLOOKUP(A28,[1]Sheet1!$C:$C,[1]Sheet1!$A:$A) -> https://youtu.be/aWJc-cT12Mc?si=A7qUwE_j4Nn_6PNN | C28: Jahan Pe Savera Ho Basera | (Baseraa 1981) | D28: =_xlfn.XLOOKUP(B28,Sheet2!B:B,Sheet2!D:D) -> Song 24
A29: UUHuIsaNTpM | B29: =_xlfn.XLOOKUP(A29,[1]Sheet1!$C:$C,[1]Sheet1!$A:$A) -> https://youtu.be/UUHuIsaNTpM?si=c6vz-9Yk28HIyiL_ | C29: Kitne Sapne Kitne Armaan | (Mere Jeevan Saathi 1972) | D29: =_xlfn.XLOOKUP(B29,Sheet2!B:B,Sheet2!D:D) -> Song 25
... A31: 30rLo4X4aI0 | B31: =_xlfn.XLOOKUP(A31,[1]Sheet1!$C:$C,[1]Sheet1!$A:$A) -> https://youtu.be/30rLo4X4aI0?si=5z-mBemInLHG5BSY | C31: Pyar Jab Na Diya Zindagi Ne Kabhi| (Sitamgar 1985) | D31: =_xlfn.XLOOKUP(B31,Sheet2!B:B,Sheet2!D:D) -> Song 27
A32: kT3rzroZSlw | B32: =_xlfn.XLOOKUP(A32,[1]Sheet1!$C:$C,[1]Sheet1!$A:$A) -> https://youtu.be/kT3rzroZSlw?si=oLL7SB-Ta9bbokKH | C32: PHIRTE HAI KABSE DARBADAR | (Duniya 1984) | D32: =_xlfn.XLOOKUP(B32,Sheet2!B:B,Sheet2!D:D) -> Song 28 | E32: Phirte Hai Kabse Darbadar | (Duniya 1984)
A33: 6GSUGstpEwY | B33: =_xlfn.XLOOKUP(A33,[1]Sheet1!$C:$C,[1]Sheet1!$A:$A) -> https://youtu.be/6GSUGstpEwY?si=fv2IS9y7Ik5mZIUG | C33: Thokar Mein Hai Meri Sara Zamana 4K | (Shehzada 1972) | D33: =_xlfn.XLOOKUP(B33,Sheet2!B:B,Sheet2!D:D) -> Song 29
A34: W29sLG5YEEU | B34: =_xlfn.XLOOKUP(A34,[1]Sheet1!$C:$C,[1]Sheet1!$A:$A) -> https://youtu.be/W29sLG5YEEU?si=jeD1MNKqRDtYo9AB | C34: Gumsum Kyun Hai Sanam | (Bhala Manas 1979) | D34: =_xlfn.XLOOKUP(B34,Sheet2!B:B,Sheet2!D:D) -> Song 30
A35: CuX6iBnHCog | B35: =_xlfn.XLOOKUP(A35,[1]Sheet1!$C:$C,[1]Sheet1!$A:$A) -> https://youtu.be/CuX6iBnHCog?si=EiQBJU1f7jSJnO5V | C35: Jaan Pehchan to Pehle se thi | (Bhala Manus 1979) | D35: =_xlfn.XLOOKUP(B35,Sheet2!B:B,Sheet2!D:D) -> Song 31
A36: 4yUauK-So28 | B36: =_xlfn.XLOOKUP(A36,[1]Sheet1!$C:$C,[1]Sheet1!$A:$A) -> https://youtu.be/4yUauK-So28?si=SWzVaVGZ8Zv5mH_O | C36: Yeh Zindagi Kuch Bhi Sahi |(Romance 1983) | D36: =_xlfn.XLOOKUP(B36,Sheet2!B:B,Sheet2!D:D) -> Song 32
A37: YQNb89xnKvQ | B37: =_xlfn.XLOOKUP(A37,[1]Sheet1!$C:$C,[1]Sheet1!$A:$A) -> https://youtu.be/YQNb89xnKvQ?si=pyGPH6aMgEP0P8Kk | C37: Tum Bin Jaoon Kahan |(Pyar Ka Mausam 1969) | D37: =_xlfn.XLOOKUP(B37,Sheet2!B:B,Sheet2!D:D) -> Song 33
A38: LblLAQQV6ko | B38: =_xlfn.XLOOKUP(A38,[1]Sheet1!$C:$C,[1]Sheet1!$A:$A) -> https://youtu.be/LblLAQQV6ko?si=-u1Xhzl87LyAqL1j | C38: Na Koi Dil Mein Samaya|( Aa Gale Lag Jaa 1973) | D38: =_xlfn.XLOOKUP(B38,Sheet2!B:B,Sheet2!D:D) -> Song 34
A39: STOM6NZfcrs | B39: =_xlfn.XLOOKUP(A39,[1]Sheet1!$C:$C,[1]Sheet1!$A:$A) -> https://youtu.be/STOM6NZfcrs?si=gXLx-s67rWOO7HYm | C39: Is Mod Se Jaate Hain| (Aandhi 1975 Songs) | D39: =_xlfn.XLOOKUP(B39,Sheet2!B:B,Sheet2!D:D) -> Song 35
A40: XxbBN4AtFio | B40: =_xlfn.XLOOKUP(A40,[1]Sheet1!$C:$C,[1]Sheet1!$A:$A) -> https://youtu.be/XxbBN4AtFio?si=fc8UNPVlvOFWQnl7 | C40: AAJA AAJA MERI JAAN | (Aja Meri Jaan) | D40: =_xlfn.XLOOKUP(B40,Sheet2!B:B,Sheet2!D:D) -> Song 36 | E40: Aaja Aaja Meri Jaan | (Aja Meri Jaan)
A41: WJyM13QI64E | B41: =_xlfn.XLOOKUP(A41,[1]Sheet1!$C:$C,[1]Sheet1!$A:$A) -> https://youtu.be/WJyM13QI64E?si=0s3hgT9czCLz6uNY | C41: Shikwa Koi Tumse Na Hai | (Joota Kahin Ka 1979) | D41: =_xlfn.XLOOKUP(B41,Sheet2!B:B,Sheet2!D:D) -> Song 37
...

Sheet Sheet1
A1: "https://youtube.com/playlist?list=PLt1_3oWrtFTOFpilXV5DEwZoxKjdXR6Ra&si=bFkh3u6LiG3dssjF",
A2: "https://youtu.be/honflNZTKHk?si=hv9Hx8Mp2K5HNxDy",
A3: https://youtu.be/sxvB0cCQBSg?si=nKHilaVWLS7HPpxw,
A4: https://youtu.be/uQvOHHGrMjg?si=tdRtS57yk-lMb4SH,
A5: https://youtu.be/pHJiYu69C4c?si=xskoVED0slaCnzR5,
A6: https://youtu.be/PBLmRYnFs7E?si=vSkvSgeTqBKEt3sO,
A7: "https://youtu.be/CpYuH4Cc8Mk?si=qK5iGgqa3qsPRKH0",
A8: "https://youtu.be/C1w6p3TEVxI?si=CkHwXCKJOBhZwWkK",
A9: "https://youtu.be/WaCRlPUPLhk?si=Nq_DXLhf7aS2DjGu",
A10: "https://youtu.be/PleWU2pdK-I?si=PK_rAjjC72uEVZrZ",
A11: "https://youtu.be/xkQpfIMj1UE?si=RerH28vnO62xX_s6",
A12: "https://youtu.be/flFE-ps5yYo?si=C90tKlW2S2fhkswP",
... A52: "https://youtu.be/K-GPX2PzDKM?si=CujGtpU8GCbhp6KW"

Sheet Sheet2
A1: <a href="#" onclick="return openBossVideo(event, | B1: https://youtu.be/CpYuH4Cc8Mk?si=qK5iGgqa3qsPRKH0 | C1: , | D1: Song 01 | E1: );"> | F1: =_xlfn.XLOOKUP(B1,youtube_video_data!B:B,youtube_video_data!C:C) -> Rah Pe Rehte Hai | Namkeen ( 1982 )
A2: 🎵 Song 01</a> | F2: =_xlfn.XLOOKUP(B2,youtube_video_data!B:B,youtube_video_data!C:C) -> 0
A3: <a href="#" onclick="return openBossVideo(event, | B3: https://youtu.be/C1w6p3TEVxI?si=CkHwXCKJOBhZwWkK | C3: , | D3: Song 02 | E3: );"> | F3: =_xlfn.XLOOKUP(B3,youtube_video_data!B:B,youtube_video_data!C:C) -> Aye Zindagi Hui Kahan Bhool Jiski | (Namumkin 1988)
A4: 🎵 Song 02</a> | F4: =_xlfn.XLOOKUP(B4,youtube_video_data!B:B,youtube_video_data!C:C) -> 0
A5: <a href="#" onclick="return openBossVideo(event, | B5: https://youtu.be/WaCRlPUPLhk?si=Nq_DXLhf7aS2DjGu | C5: , | D5: Song 03 | E5: );"> | F5: =_xlfn.XLOOKUP(B5,youtube_video_data!B:B,youtube_video_data!C:C) -> Na Jaane Din Kaise (Both Parts) | (Chala Murari Hero Banne 1977)
A6: 🎵 Song 03</a> | F6: =_xlfn.XLOOKUP(B6,youtube_video_data!B:B,youtube_video_data!C:C) -> 0
A7: <a href="#" onclick="return openBossVideo(event, | B7: https://youtu.be/PleWU2pdK-I?si=PK_rAjjC72uEVZrZ | C7: , | D7: Song 04 | E7: );"> | F7: =_xlfn.XLOOKUP(B7,youtube_video_data!B:B,youtube_video_data!C:C) -> Main Shayar Badnam | (Namak Haraam 1973)
A8: 🎵 Song 04</a> | F8: =_xlfn.XLOOKUP(B8,youtube_video_data!B:B,youtube_video_data!C:C) -> 0
A9: <a href="#" onclick="return openBossVideo(event, | B9: https://youtu.be/xkQpfIMj1UE?si=RerH28vnO62xX_s6 | C9: , | D9: Song 05 | E9: );"> | F9: =_xlfn.XLOOKUP(B9,youtube_video_data!B:B,youtube_video_data!C:C) -> Mujhko Yuhi Udaas | (Khushboo (1975)
A10: 🎵 Song 05</a> | F10: =_xlfn.XLOOKUP(B10,youtube_video_data!B:B,youtube_video_data!C:C) -> 0
A11: <a href="#" onclick="return openBossVideo(event, | B11: https://youtu.be/flFE-ps5yYo?si=C90tKlW2S2fhkswP | C11: , | D11: Song 06 | E11: );"> | F11: =_xlfn.XLOOKUP(B11,youtube_video_data!B:B,youtube_video_data!C:C) -> Tumne Mujhe Dekha | (Teesri Manzil 1966)
A12: 🎵 Song 06</a> | F12: =_xlfn.XLOOKUP(B12,youtube_video_data!B:B,youtube_video_data!C:C) -> 0
A13: <a href="#" onclick="return openBossVideo(event, | B13: https://youtu.be/tC11eSDHobE?si=LpParr0eIVJHpLeT | C13: , | D13: Song 07 | E13: );"> | F13: =_xlfn.XLOOKUP(B13,youtube_video_data!B:B,youtube_video_data!C:C) -> A Ri Pawan Dhunde Kise Tera Mann | ( Bemisaal 1982)
A14: 🎵 Song 07</a> | F14: =_xlfn.XLOOKUP(B14,youtube_video_data!B:B,youtube_video_data!C:C) -> 0
A15: <a href="#" onclick="return openBossVideo(event, | B15: https://youtu.be/2fUVcrMA8Dg?si=bXt_fKwl3TEJiqiY | C15: , | D15: Song 08 | E15: );"> | F15: =_xlfn.XLOOKUP(B15,youtube_video_data!B:B,youtube_video_data!C:C) -> Kisi Baat Pe Main Kisise Khafa Hoon | ( Bemisaal 1982)
A16: 🎵 Song 08</a> | F16: =_xlfn.XLOOKUP(B16,youtube_video_data!B:B,youtube_video_data!C:C) -> 0
A17: <a href="#" onclick="return openBossVideo(event, | B17: https://youtu.be/0VbyQ5tdavI?si=IP277RozQo8C-FBe | C17: , | D17: Song 09 | E17: );"> | F17: =_xlfn.XLOOKUP(B17,youtube_video_data!B:B,youtube_video_data!C:C) -> Sawan Ke Jhoole| (Jurmana 1979)
A18: 🎵 Song 09</a> | F18: =_xlfn.XLOOKUP(B18,youtube_video_data!B:B,youtube_video_data!C:C) -> 0
A19: <a href="#" onclick="return openBossVideo(event, | B19: https://youtu.be/iaLmf7L-B24?si=YV8cIZJ5yHJUapXE | C19: , | D19: Song 10 | E19: );"> | F19: =_xlfn.XLOOKUP(B19,youtube_video_data!B:B,youtube_video_data!C:C) -> Oh Hansini | (Zehreela Insaan 1974)
A20: 🎵 Song 10</a> | F20: =_xlfn.XLOOKUP(B20,youtube_video_data!B:B,youtube_video_data!C:C) -> 0
A21: <a href="#" onclick="return openBossVideo(event, | B21: https://youtu.be/RscsV4uuetw?si=HUEUjhme8qBCWgTd | C21: , | D21: Song 11 | E21: );"> | F21: =_xlfn.XLOOKUP(B21,youtube_video_data!B:B,youtube_video_data!C:C) -> Jidhar Dekhoon Teri Tasveer | (Mahaan 1983)
A22: 🎵 Song 11</a> | F22: =_xlfn.XLOOKUP(B22,youtube_video_data!B:B,youtube_video_data!C:C) -> 0
A23: <a href="#" onclick="return openBossVideo(event, | B23: https://youtu.be/ADYDEx1pvEg?si=WKjpAxfpZMgEWOOy | C23: , | D23: Song 12 | E23: );"> | F23: =_xlfn.XLOOKUP(B23,youtube_video_data!B:B,youtube_video_data!C:C) -> KYA JAANU SAJAN HOTI HAI | (BAHARON KE SAPNE 1967)
A24: 🎵 Song 12</a> | F24: =_xlfn.XLOOKUP(B24,youtube_video_data!B:B,youtube_video_data!C:C) -> 0
A25: <a href="#" onclick="return openBossVideo(event, | B25: https://youtu.be/PZzK3CVzLKo?si=y9ntwMjpZFCPp6dU | C25: , | D25: Song 13 | E25: );"> | F25: =_xlfn.XLOOKUP(B25,youtube_video_data!B:B,youtube_video_data!C:C) -> Katra Katra Milti Hai Katra Katra Jeene Do | (Ijaazat 1987)
A26: 🎵 Song 13</a> | F26: =_xlfn.XLOOKUP(B26,youtube_video_data!B:B,youtube_video_data!C:C) -> 0
A27: <a href="#" onclick="return openBossVideo(event, | B27: https://youtu.be/wVlsl3QXwKU?si=u-ReqZGUQX_0Gi36 | C27: , | D27: Song 14 | E27: );"> | F27: =_xlfn.XLOOKUP(B27,youtube_video_data!B:B,youtube_video_data!C:C) -> Dhanno Ki Aankhon Me | (Kitaab 1977)
A28: 🎵 Song 14</a> | F28: =_xlfn.XLOOKUP(B28,youtube_video_data!B:B,youtube_video_data!C:C) -> 0
A29: <a href="#" onclick="return openBossVideo(event, | B29: https://youtu.be/M_mA1M44Bwc?si=wwIEDgVbo6a2_DoT | C29: , | D29: Song 15 | E29: );"> | F29: =_xlfn.XLOOKUP(B29,youtube_video_data!B:B,youtube_video_data!C:C) -> Subha Serial Title Song | (Subah 1987)
A30: 🎵 Song 15</a> | F30: =_xlfn.XLOOKUP(B30,youtube_video_data!B:B,youtube_video_data!C:C) -> 0
A31: <a href="#" onclick="return openBossVideo(event, | B31: https://youtu.be/t6iLjbkxBZo?si=IZYjFNUaK22H1qlN | C31: , | D31: Song 16 | E31: );"> | F31: =_xlfn.XLOOKUP(B31,youtube_video_data!B:B,youtube_video_data!C:C) -> Masterji ki aa gayi chitthi | (Kitaab 1977)
A32: 🎵 Song 16</a> | F32: =_xlfn.XLOOKUP(B32,youtube_video_data!B:B,youtube_video_data!C:C) -> 0
A33: <a href="#" onclick="return openBossVideo(event, | B33: https://youtu.be/8t5Rt_LWmpE?si=cVRNkFxngFAPwxtq | C33: , | D33: Song 17 | E33: );"> | F33: =_xlfn.XLOOKUP(B33,youtube_video_data!B:B,youtube_video_data!C:C) -> Samundar Mein Nahake | (Pukar 1983)
A34: 🎵 Song 17</a> | F34: =_xlfn.XLOOKUP(B34,youtube_video_data!B:B,youtube_video_data!C:C) -> 0
A35: <a href="#" onclick="return openBossVideo(event, | B35: https://youtu.be/h34dmUw_yCQ?si=kBKlVoNxUkzEiJy3 | C35: , | D35: Song 18 | E35: );"> | F35: =_xlfn.XLOOKUP(B35,youtube_video_data!B:B,youtube_video_data!C:C) -> Phir Wahi Raat | (Ghar 1978)
A36: 🎵 Song 18</a> | F36: =_xlfn.XLOOKUP(B36,youtube_video_data!B:B,youtube_video_data!C:C) -> 0
A37: <a href="#" onclick="return openBossVideo(event, | B37: https://youtu.be/h34dmUw_yCQ?si=McXdbMdvr6zHm6xf | C37: , | D37: Song 19 | E37: );"> | F37: =_xlfn.XLOOKUP(B37,youtube_video_data!B:B,youtube_video_data!C:C) -> #N/A
A38: 🎵 Song 19</a> | F38: =_xlfn.XLOOKUP(B38,youtube_video_data!B:B,youtube_video_data!C:C) -> 0
A39: <a href="#" onclick="return openBossVideo(event, | B39: https://youtu.be/kkTv_aUjd5Y?si=TCkKvKpl_76ovFE8 | C39: , | D39: Song 20 | E39: );"> | F39: =_xlfn.XLOOKUP(B39,youtube_video_data!B:B,youtube_video_data!C:C) -> Phulon Ki Duniya Se | (Rickshawala 1973)
A40: 🎵 Song 20</a> | F40: =_xlfn.XLOOKUP(B40,youtube_video_data!B:B,youtube_video_data!C:C) -> 0
...
